#VRML_SIM R2023b utf8

EXTERNPROTO "https://raw.githubusercontent.com/cyberbotics/webots/R2023b/projects/objects/backgrounds/protos/TexturedBackground.proto"
EXTERNPROTO "https://raw.githubusercontent.com/cyberbotics/webots/R2023b/projects/objects/backgrounds/protos/TexturedBackgroundLight.proto"
EXTERNPROTO "https://raw.githubusercontent.com/cyberbotics/webots/R2023b/projects/objects/floors/protos/RectangleArena.proto"

WorldInfo {
}
Viewpoint {
  orientation -0.21575399383586896 -0.13203358172896432 0.9674798951087784 4.839993539704815
  position 0.27409368441007304 2.3777193123835243 1.1783113757102834
}
TexturedBackground {
}
TexturedBackgroundLight {
}
RectangleArena {
  translation 0 0 -1.22
  floorSize 5 5
}
DEF Robot Robot {
  children [
    Pose {
      translation -0.0467 0.047 0.0252
      rotation 1 0 0 -3.1415923071795864
      children [
        DEF SCREW Group {
          children [
            Transform {
              scale 1.1 1.1 1.1
              children [
                Shape {
                  appearance PBRAppearance {
                    baseColorMap ImageTexture {
                      url [
                        "https://raw.githubusercontent.com/cyberbotics/webots/R2023b/projects/appearances/protos/textures/old_steel/old_steel_base_color.jpg"
                      ]
                    }
                    roughnessMap ImageTexture {
                      url [
                        "https://raw.githubusercontent.com/cyberbotics/webots/R2023b/projects/appearances/protos/textures/old_steel/old_steel_roughness.jpg"
                      ]
                    }
                    metalnessMap ImageTexture {
                      url [
                        "https://raw.githubusercontent.com/cyberbotics/webots/R2023b/projects/appearances/protos/textures/old_steel/old_steel_metalness.jpg"
                      ]
                    }
                    normalMap ImageTexture {
                      url [
                        "https://raw.githubusercontent.com/cyberbotics/webots/R2023b/projects/appearances/protos/textures/old_steel/old_steel_normal.jpg"
                      ]
                    }
                  }
                  geometry Mesh {
                    url [
                      "https://raw.githubusercontent.com/cyberbotics/webots/R2023b/projects/robots/universal_robots/protos/UR5e/meshes/screw.obj"
                    ]
                  }
                }
              ]
            }
            DEF CYLINDER Pose {
              translation 0 0 0.02
              children [
                Shape {
                  appearance PBRAppearance {
                    baseColorMap ImageTexture {
                      url [
                        "https://raw.githubusercontent.com/cyberbotics/webots/R2023b/projects/appearances/protos/textures/screw_thread/screw_thread_base_color.jpg"
                      ]
                    }
                    roughnessMap ImageTexture {
                      url [
                        "https://raw.githubusercontent.com/cyberbotics/webots/R2023b/projects/appearances/protos/textures/screw_thread/screw_thread_roughness.jpg"
                      ]
                    }
                    normalMap ImageTexture {
                      url [
                        "https://raw.githubusercontent.com/cyberbotics/webots/R2023b/projects/appearances/protos/textures/screw_thread/screw_thread_normal.jpg"
                      ]
                    }
                    occlusionMap ImageTexture {
                      url [
                        "https://raw.githubusercontent.com/cyberbotics/webots/R2023b/projects/appearances/protos/textures/screw_thread/screw_thread_occlusion.jpg"
                      ]
                    }
                    textureTransform TextureTransform {
                      rotation 1.5708
                      scale 1.6 2
                    }
                  }
                  geometry Cylinder {
                    height 0.04
                    radius 0.0044
                  }
                }
              ]
            }
          ]
        }
      ]
    }
    Pose {
      translation -0.0467 -0.047 0.0252
      rotation 1 0 0 -3.1415923071795864
      children [
        USE SCREW
      ]
    }
    Pose {
      translation 0.0464 -0.047 0.0252
      rotation 1 0 0 -3.1415923071795864
      children [
        USE SCREW
      ]
    }
    Pose {
      translation 0.0464 0.047 0.0252
      rotation 1 0 0 -3.1415923071795864
      children [
        USE SCREW
      ]
    }
    Shape {
      appearance DEF METAL_APPEARANCE PBRAppearance {
        baseColor 0.6 0.6 0.6
        roughness 0.7
      }
      geometry Mesh {
        url [
          "https://raw.githubusercontent.com/cyberbotics/webots/R2023b/projects/robots/universal_robots/protos/UR5e/meshes/base_link_0.obj"
        ]
      }
    }
    Shape {
      appearance DEF JOINT_APPEARANCE PBRAppearance {
        baseColor 0 0 0
        roughness 1
        metalness 0
      }
      geometry Mesh {
        url [
          "https://raw.githubusercontent.com/cyberbotics/webots/R2023b/projects/robots/universal_robots/protos/UR5e/meshes/base_link_1.obj"
        ]
      }
    }
    HingeJoint {
      jointParameters HingeJointParameters {
        position -1.5094473304206406e-05
        axis 0 0 1
        anchor 0 0 0.163
      }
      device [
        RotationalMotor {
          name "shoulder_pan_joint"
          maxVelocity 3.14
          minPosition -6.28318530718
          maxPosition 6.28318530718
          maxTorque 150
        }
        PositionSensor {
          name "shoulder_pan_joint_sensor"
        }
      ]
      endPoint Solid {
        translation 0 0 0.163
        rotation 0 0 -1 1.5094486471170026e-05
        children [
          Shape {
            appearance USE METAL_APPEARANCE
            geometry Mesh {
              url [
                "https://raw.githubusercontent.com/cyberbotics/webots/R2023b/projects/robots/universal_robots/protos/UR5e/meshes/shoulder_link_0.obj"
              ]
            }
          }
          Shape {
            appearance USE JOINT_APPEARANCE
            geometry Mesh {
              url [
                "https://raw.githubusercontent.com/cyberbotics/webots/R2023b/projects/robots/universal_robots/protos/UR5e/meshes/shoulder_link_1.obj"
              ]
            }
          }
          Shape {
            appearance PBRAppearance {
              baseColor 0.4902 0.678431 0.8
              roughness 0.4
              metalness 0
              normalMap ImageTexture {
                url [
                  "https://raw.githubusercontent.com/cyberbotics/webots/R2023b/projects/robots/universal_robots/protos/UR5e/textures/normal_0.jpg"
                ]
              }
              occlusionMap ImageTexture {
                url [
                  "https://raw.githubusercontent.com/cyberbotics/webots/R2023b/projects/robots/universal_robots/protos/UR5e/textures/occlusion_0.jpg"
                ]
              }
            }
            geometry Mesh {
              url [
                "https://raw.githubusercontent.com/cyberbotics/webots/R2023b/projects/robots/universal_robots/protos/UR5e/meshes/shoulder_link_2.obj"
              ]
            }
          }
          Shape {
            appearance DEF SCREW_APPEARANCE PBRAppearance {
            }
            geometry Mesh {
              url [
                "https://raw.githubusercontent.com/cyberbotics/webots/R2023b/projects/robots/universal_robots/protos/UR5e/meshes/shoulder_link_3.obj"
              ]
            }
          }
          HingeJoint {
            jointParameters HingeJointParameters {
              position -1.5707780643659623
              axis 0 1 0
              anchor 0 0.138 0
            }
            device [
              RotationalMotor {
                name "shoulder_lift_joint"
                maxVelocity 3.14
                minPosition -6.28318530718
                maxPosition 6.28318530718
                maxTorque 150
              }
              PositionSensor {
                name "shoulder_lift_joint_sensor"
              }
            ]
            endPoint Solid {
              translation 0.0023795853406054558 0.13472673434860294 0.01215357030283812
              rotation 0 0.9999999999999999 0 0.010775037044571037
              children [
                Shape {
                  appearance PBRAppearance {
                    baseColor 0.4902 0.678431 0.8
                    roughness 0.4
                    metalness 0
                    normalMap ImageTexture {
                      url [
                        "https://raw.githubusercontent.com/cyberbotics/webots/R2023b/projects/robots/universal_robots/protos/UR5e/textures/normal_1.jpg"
                      ]
                    }
                    occlusionMap ImageTexture {
                      url [
                        "https://raw.githubusercontent.com/cyberbotics/webots/R2023b/projects/robots/universal_robots/protos/UR5e/textures/occlusion_1.jpg"
                      ]
                    }
                  }
                  geometry Mesh {
                    url [
                      "https://raw.githubusercontent.com/cyberbotics/webots/R2023b/projects/robots/universal_robots/protos/UR5e/meshes/upper_arm_link_0.obj"
                    ]
                  }
                }
                Shape {
                  appearance USE SCREW_APPEARANCE
                  geometry Mesh {
                    url [
                      "https://raw.githubusercontent.com/cyberbotics/webots/R2023b/projects/robots/universal_robots/protos/UR5e/meshes/upper_arm_link_1.obj"
                    ]
                  }
                }
                Shape {
                  appearance USE METAL_APPEARANCE
                  geometry Mesh {
                    url [
                      "https://raw.githubusercontent.com/cyberbotics/webots/R2023b/projects/robots/universal_robots/protos/UR5e/meshes/upper_arm_link_2.obj"
                    ]
                  }
                }
                Shape {
                  appearance USE JOINT_APPEARANCE
                  geometry Mesh {
                    url [
                      "https://raw.githubusercontent.com/cyberbotics/webots/R2023b/projects/robots/universal_robots/protos/UR5e/meshes/upper_arm_link_3.obj"
                    ]
                  }
                }
                Shape {
                  appearance PBRAppearance {
                    baseColor 0.4902 0.678431 0.8
                    roughness 0.4
                    metalness 0
                    normalMap ImageTexture {
                      url [
                        "https://raw.githubusercontent.com/cyberbotics/webots/R2023b/projects/robots/universal_robots/protos/UR5e/textures/normal_2.jpg"
                      ]
                    }
                    occlusionMap ImageTexture {
                      url [
                        "https://raw.githubusercontent.com/cyberbotics/webots/R2023b/projects/robots/universal_robots/protos/UR5e/textures/occlusion_2.jpg"
                      ]
                    }
                  }
                  geometry Mesh {
                    url [
                      "https://raw.githubusercontent.com/cyberbotics/webots/R2023b/projects/robots/universal_robots/protos/UR5e/meshes/upper_arm_link_4.obj"
                    ]
                  }
                }
                Shape {
                  appearance USE SCREW_APPEARANCE
                  geometry Mesh {
                    url [
                      "https://raw.githubusercontent.com/cyberbotics/webots/R2023b/projects/robots/universal_robots/protos/UR5e/meshes/upper_arm_link_5.obj"
                    ]
                  }
                }
                Shape {
                  appearance DEF METAL_APPEARANCE_LIGHT PBRAppearance {
                    roughness 0.7
                  }
                  geometry Mesh {
                    url [
                      "https://raw.githubusercontent.com/cyberbotics/webots/R2023b/projects/robots/universal_robots/protos/UR5e/meshes/upper_arm_link_6.obj"
                    ]
                  }
                }
                Shape {
                  appearance USE JOINT_APPEARANCE
                  geometry Mesh {
                    url [
                      "https://raw.githubusercontent.com/cyberbotics/webots/R2023b/projects/robots/universal_robots/protos/UR5e/meshes/upper_arm_link_7.obj"
                    ]
                  }
                }
                Shape {
                  appearance USE METAL_APPEARANCE
                  geometry Mesh {
                    url [
                      "https://raw.githubusercontent.com/cyberbotics/webots/R2023b/projects/robots/universal_robots/protos/UR5e/meshes/upper_arm_link_8.obj"
                    ]
                  }
                }
                Shape {
                  appearance USE JOINT_APPEARANCE
                  geometry Mesh {
                    url [
                      "https://raw.githubusercontent.com/cyberbotics/webots/R2023b/projects/robots/universal_robots/protos/UR5e/meshes/upper_arm_link_9.obj"
                    ]
                  }
                }
                HingeJoint {
                  jointParameters HingeJointParameters {
                    position 1.5708138153775235
                    axis 0 1 0
                    anchor 0 -0.131 0.425
                  }
                  device [
                    RotationalMotor {
                      name "elbow_joint"
                      maxVelocity 3.14
                      minPosition -3.14159265359
                      maxPosition 3.14159265359
                      maxTorque 150
                    }
                    PositionSensor {
                      name "elbow_joint_sensor"
                    }
                  ]
                  endPoint Solid {
                    translation 0 -0.131 0.425
                    rotation 0 1 0 1.5708138153775235
                    children [
                      Shape {
                        appearance USE METAL_APPEARANCE
                        geometry Mesh {
                          url [
                            "https://raw.githubusercontent.com/cyberbotics/webots/R2023b/projects/robots/universal_robots/protos/UR5e/meshes/forearm_link_0.obj"
                          ]
                        }
                      }
                      Shape {
                        appearance USE METAL_APPEARANCE
                        geometry Mesh {
                          url [
                            "https://raw.githubusercontent.com/cyberbotics/webots/R2023b/projects/robots/universal_robots/protos/UR5e/meshes/forearm_link_1.obj"
                          ]
                        }
                      }
                      Shape {
                        appearance USE JOINT_APPEARANCE
                        geometry Mesh {
                          url [
                            "https://raw.githubusercontent.com/cyberbotics/webots/R2023b/projects/robots/universal_robots/protos/UR5e/meshes/forearm_link_2.obj"
                          ]
                        }
                      }
                      Shape {
                        appearance USE METAL_APPEARANCE_LIGHT
                        geometry Mesh {
                          url [
                            "https://raw.githubusercontent.com/cyberbotics/webots/R2023b/projects/robots/universal_robots/protos/UR5e/meshes/forearm_link_3.obj"
                          ]
                        }
                      }
                      Shape {
                        appearance USE JOINT_APPEARANCE
                        geometry Mesh {
                          url [
                            "https://raw.githubusercontent.com/cyberbotics/webots/R2023b/projects/robots/universal_robots/protos/UR5e/meshes/forearm_link_4.obj"
                          ]
                        }
                      }
                      Shape {
                        appearance PBRAppearance {
                          baseColor 0.4902 0.678431 0.8
                          roughness 0.4
                          metalness 0
                          normalMap ImageTexture {
                            url [
                              "https://raw.githubusercontent.com/cyberbotics/webots/R2023b/projects/robots/universal_robots/protos/UR5e/textures/normal_3.jpg"
                            ]
                          }
                          occlusionMap ImageTexture {
                            url [
                              "https://raw.githubusercontent.com/cyberbotics/webots/R2023b/projects/robots/universal_robots/protos/UR5e/textures/occlusion_3.jpg"
                            ]
                          }
                        }
                        geometry Mesh {
                          url [
                            "https://raw.githubusercontent.com/cyberbotics/webots/R2023b/projects/robots/universal_robots/protos/UR5e/meshes/forearm_link_5.obj"
                          ]
                        }
                      }
                      Shape {
                        appearance USE SCREW_APPEARANCE
                        geometry Mesh {
                          url [
                            "https://raw.githubusercontent.com/cyberbotics/webots/R2023b/projects/robots/universal_robots/protos/UR5e/meshes/forearm_link_6.obj"
                          ]
                        }
                      }
                      Shape {
                        appearance USE JOINT_APPEARANCE
                        geometry Mesh {
                          url [
                            "https://raw.githubusercontent.com/cyberbotics/webots/R2023b/projects/robots/universal_robots/protos/UR5e/meshes/forearm_link_7.obj"
                          ]
                        }
                      }
                      HingeJoint {
                        jointParameters HingeJointParameters {
                          position -1.5707946963204928
                          axis 0 1 0
                          anchor 0 0 0.392
                        }
                        device [
                          RotationalMotor {
                            name "wrist_1_joint"
                            maxVelocity 6.28
                            minPosition -6.28318530718
                            maxPosition 6.28318530718
                            maxTorque 28
                          }
                          PositionSensor {
                            name "wrist_1_joint_sensor"
                          }
                        ]
                        endPoint Solid {
                          translation 0 0 0.392
                          rotation 0 0.9999999999999999 0 1.3038303169147816e-06
                          children [
                            Shape {
                              appearance USE METAL_APPEARANCE
                              geometry Mesh {
                                url [
                                  "https://raw.githubusercontent.com/cyberbotics/webots/R2023b/projects/robots/universal_robots/protos/UR5e/meshes/wrist_1_link_0.obj"
                                ]
                              }
                            }
                            Shape {
                              appearance PBRAppearance {
                                baseColor 0.4902 0.678431 0.8
                                roughness 0.4
                                metalness 0
                                normalMap ImageTexture {
                                  url [
                                    "https://raw.githubusercontent.com/cyberbotics/webots/R2023b/projects/robots/universal_robots/protos/UR5e/textures/normal_4.jpg"
                                  ]
                                }
                                occlusionMap ImageTexture {
                                  url [
                                    "https://raw.githubusercontent.com/cyberbotics/webots/R2023b/projects/robots/universal_robots/protos/UR5e/textures/occlusion_4.jpg"
                                  ]
                                }
                              }
                              geometry Mesh {
                                url [
                                  "https://raw.githubusercontent.com/cyberbotics/webots/R2023b/projects/robots/universal_robots/protos/UR5e/meshes/wrist_1_link_1.obj"
                                ]
                              }
                            }
                            Shape {
                              appearance USE SCREW_APPEARANCE
                              geometry Mesh {
                                url [
                                  "https://raw.githubusercontent.com/cyberbotics/webots/R2023b/projects/robots/universal_robots/protos/UR5e/meshes/wrist_1_link_2.obj"
                                ]
                              }
                            }
                            Shape {
                              appearance USE JOINT_APPEARANCE
                              geometry Mesh {
                                url [
                                  "https://raw.githubusercontent.com/cyberbotics/webots/R2023b/projects/robots/universal_robots/protos/UR5e/meshes/wrist_1_link_3.obj"
                                ]
                              }
                            }
                            HingeJoint {
                              jointParameters HingeJointParameters {
                                position -1.5707963267811966
                                axis 0 0 1
                                anchor 0 0.127 0
                              }
                              device [
                                RotationalMotor {
                                  name "wrist_2_joint"
                                  maxVelocity 6.28
                                  minPosition -6.28318530718
                                  maxPosition 6.28318530718
                                  maxTorque 28
                                }
                                PositionSensor {
                                  name "wrist_2_joint_sensor"
                                }
                              ]
                              endPoint Solid {
                                translation 0 0.127 0
                                rotation 0 0 -1 1.5707963267811964
                                children [
                                  Shape {
                                    appearance USE METAL_APPEARANCE
                                    geometry Mesh {
                                      url [
                                        "https://raw.githubusercontent.com/cyberbotics/webots/R2023b/projects/robots/universal_robots/protos/UR5e/meshes/wrist_2_link_0.obj"
                                      ]
                                    }
                                  }
                                  Shape {
                                    appearance PBRAppearance {
                                      baseColor 0.4902 0.678431 0.8
                                      roughness 0.4
                                      metalness 0
                                      normalMap ImageTexture {
                                        url [
                                          "https://raw.githubusercontent.com/cyberbotics/webots/R2023b/projects/robots/universal_robots/protos/UR5e/textures/normal_5.jpg"
                                        ]
                                      }
                                      occlusionMap ImageTexture {
                                        url [
                                          "https://raw.githubusercontent.com/cyberbotics/webots/R2023b/projects/robots/universal_robots/protos/UR5e/textures/occlusion_5.jpg"
                                        ]
                                      }
                                    }
                                    geometry Mesh {
                                      url [
                                        "https://raw.githubusercontent.com/cyberbotics/webots/R2023b/projects/robots/universal_robots/protos/UR5e/meshes/wrist_2_link_1.obj"
                                      ]
                                    }
                                  }
                                  Shape {
                                    appearance USE SCREW_APPEARANCE
                                    geometry Mesh {
                                      url [
                                        "https://raw.githubusercontent.com/cyberbotics/webots/R2023b/projects/robots/universal_robots/protos/UR5e/meshes/wrist_2_link_2.obj"
                                      ]
                                    }
                                  }
                                  Shape {
                                    appearance USE JOINT_APPEARANCE
                                    geometry Mesh {
                                      url [
                                        "https://raw.githubusercontent.com/cyberbotics/webots/R2023b/projects/robots/universal_robots/protos/UR5e/meshes/wrist_2_link_3.obj"
                                      ]
                                    }
                                  }
                                  HingeJoint {
                                    jointParameters HingeJointParameters {
                                      position 4.075260144840076e-07
                                      axis 0 1 0
                                      anchor 0 0 0.1
                                    }
                                    device [
                                      RotationalMotor {
                                        name "wrist_3_joint"
                                        maxVelocity 6.28
                                        minPosition -6.28318530718
                                        maxPosition 6.28318530718
                                        maxTorque 28
                                      }
                                      PositionSensor {
                                        name "wrist_3_joint_sensor"
                                      }
                                    ]
                                    endPoint Solid {
                                      translation -2.273267579918143e-06 4.57353322724749e-06 0.09998708956822644
                                      rotation -0.5887360810153457 0.8077351342369655 0.030883326081939916 6.151130032703392e-07
                                      children [
                                        Shape {
                                          appearance USE METAL_APPEARANCE
                                          geometry Mesh {
                                            url [
                                              "https://raw.githubusercontent.com/cyberbotics/webots/R2023b/projects/robots/universal_robots/protos/UR5e/meshes/wrist_3_link_0.obj"
                                            ]
                                          }
                                        }
                                        Pose {
                                          translation 0 0.1 0
                                        }
                                      ]
                                      name "wrist_3_link"
                                      boundingObject Group {
                                        children [
                                          Pose {
                                            translation 0 0.07 0
                                            rotation 1 0 0 -1.57079632679
                                            children [
                                              Cylinder {
                                                height 0.048
                                                radius 0.038
                                              }
                                            ]
                                          }
                                          Pose {
                                            translation 0 0.09 0
                                            rotation 1 0 0 -1.57079632679
                                            children [
                                              Cylinder {
                                                height 0.018
                                                radius 0.032
                                              }
                                            ]
                                          }
                                        ]
                                      }
                                      physics Physics {
                                        density -1
                                        mass 0.365
                                        centerOfMass [
                                          0 0.071 0
                                        ]
                                      }
                                      linearVelocity -2.1020611184612515e-05 8.215321417453645e-05 -1.0120467305718542e-07
                                      angularVelocity 4.0625202509443334e-07 2.5499603765565206e-07 0.00016914716864926328
                                    }
                                  }
                                ]
                                name "wrist_2_link"
                                boundingObject Group {
                                  children [
                                    Pose {
                                      translation 0 -0.001 0.0995
                                      rotation 1 0 0 -1.57079632679
                                      children [
                                        Cylinder {
                                          height 0.108
                                          radius 0.04
                                        }
                                      ]
                                    }
                                    Pose {
                                      translation 0 -0.001 0.0676
                                      children [
                                        Cylinder {
                                          height 0.043
                                          radius 0.038
                                        }
                                      ]
                                    }
                                  ]
                                }
                                physics Physics {
                                  density -1
                                  mass 1.3
                                  centerOfMass [
                                    0 0 0.1
                                  ]
                                }
                                linearVelocity -2.1005942878314724e-05 8.227013029746017e-05 -1.0141735894343553e-07
                                angularVelocity 4.067261999116562e-07 2.552426795858326e-07 0.00016910194037077306
                              }
                            }
                          ]
                          name "wrist_1_link"
                          boundingObject Group {
                            children [
                              Pose {
                                translation 0 0.089 0
                                rotation 1 0 0 -1.57079632679
                                children [
                                  Cylinder {
                                    height 0.086
                                    radius 0.038
                                  }
                                ]
                              }
                              Pose {
                                translation 0 0.126 0
                                children [
                                  Cylinder {
                                    height 0.112
                                    radius 0.038
                                  }
                                ]
                              }
                            ]
                          }
                          physics Physics {
                            density -1
                            mass 1.37
                            centerOfMass [
                              0 0.127 0
                            ]
                          }
                          linearVelocity -2.105548107375228e-05 6.555370527333885e-05 -7.59880339226827e-08
                          angularVelocity 4.0813131168188723e-07 2.5555439443150705e-07 0.00016912160221585872
                        }
                      }
                    ]
                    name "forearm_link"
                    boundingObject Group {
                      children [
                        Pose {
                          translation 0 0 0.207
                          children [
                            Cylinder {
                              height 0.36
                              radius 0.038
                            }
                          ]
                        }
                        Pose {
                          translation 0 -0.001 0.39
                          rotation 1 0 0 -1.57079632679
                          children [
                            Cylinder {
                              height 0.109
                              radius 0.039
                            }
                          ]
                        }
                        Pose {
                          translation 0 0.06 0
                          rotation 1 0 0 1.57079632679
                          children [
                            Capsule {
                              height 0.05
                              radius 0.058
                              subdivision 16
                            }
                          ]
                        }
                        Pose {
                          translation 0 0 0.07
                          children [
                            Capsule {
                              height 0.1
                              radius 0.04
                              subdivision 16
                            }
                          ]
                        }
                      ]
                    }
                    physics Physics {
                      density -1
                      mass 2.846
                      centerOfMass [
                        0 0 0.15
                      ]
                    }
                    linearVelocity 3.2506930310360144e-07 2.4964431324023915e-05 -6.60452754720478e-08
                    angularVelocity 4.0928707976725375e-07 2.5593383739966825e-07 0.00016915447320355395
                  }
                }
              ]
              name "upper_arm_link"
              boundingObject Group {
                children [
                  Pose {
                    translation 0 0 0.22
                    children [
                      Cylinder {
                        height 0.407
                        radius 0.059
                      }
                    ]
                  }
                  Pose {
                    rotation 1 0 0 -1.57079632679
                    children [
                      Cylinder {
                        height 0.133
                        radius 0.059
                      }
                    ]
                  }
                  Pose {
                    translation 0 -0.005 0.424
                    rotation 1 0 0 -1.57079632679
                    children [
                      Cylinder {
                        height 0.149
                        radius 0.059
                      }
                    ]
                  }
                ]
              }
              physics Physics {
                density -1
                mass 8.058
                centerOfMass [
                  0 0 0.2125
                ]
              }
              linearVelocity -2.201462140136275e-05 -2.4306462138832727e-07 2.6665482779832985e-08
              angularVelocity 4.1228358389693934e-07 2.568503205839153e-07 0.00016935876710347545
            }
          }
        ]
        name "shoulder_link"
        boundingObject Group {
          children [
            Pose {
              children [
                Cylinder {
                  height 0.135
                  radius 0.059
                }
              ]
            }
            Pose {
              translation 0 0.03 0
              rotation 1 0 0 -1.57079632679
              children [
                Cylinder {
                  height 0.093
                  radius 0.059
                }
              ]
            }
          ]
        }
        physics Physics {
          density -1
          mass 3.761
          centerOfMass [
            0 -0.02561 0.00193
          ]
        }
        linearVelocity 4.714983864206803e-06 -4.7067067539250123e-07 -5.227893978324813e-09
        angularVelocity 2.0972086645840067e-07 1.152569556474299e-07 0.0001695565423837634
      }
    }
  ]
  name "UR5e"
  model "UR5e"
  boundingObject Pose {
    translation 0 0 0.05
    children [
      Cylinder {
        height 0.1
        radius 0.076
      }
    ]
  }
  controller "controller_test"
  supervisor TRUE
  selfCollision TRUE
}
DEF Arm Solid {
  translation 1.19784 0 0.507323
  rotation 0 1 0 -2.094395307179586
  children [
    Shape {
      appearance Appearance {
        material Material {
          diffuseColor 1 0 0.2
        }
      }
      geometry Cylinder {
        height 0.4
        radius 0.05
      }
    }
  ]
  boundingObject DEF arm Cylinder {
    height 0.4
    radius 0.05
  }
}
DEF Box Solid {
  translation 1.09 0.07 0.95001
  rotation 0 1 0 -3.1415853071795863
  children [
    Shape {
      appearance Appearance {
        material Material {
          diffuseColor 1 1 0
        }
      }
      geometry Box {
        size 0.1 0.1 0.1
      }
    }
  ]
  name "solid(2)"
}
DEF Table Solid {
  translation 0.33 0 -0.03
  children [
    Shape {
      appearance Appearance {
        material Material {
          diffuseColor 0.5 0.5 0.5
        }
      }
      geometry Box {
        size 1 1 0.03
      }
    }
  ]
  name "solid(1)"
  boundingObject DEF table Box {
    size 1 1 0.03
  }
}
